<?xml version="1.0"?>
<robot name="scara">

<material name="blue">
    <color rgba="0 0 0.8 0.6"/>
  </material>
  <material name="green">
    <color rgba="0 1 0 0.6"/>
  </material>
  <material name="yellow">
    <color rgba="1 1 0 0.6"/>
  </material>
  <material name="red">
    <color rgba="1 0 0 0.6"/>
  </material>

<!--  base_link-->
  <link name="base_link">
    <visual>
      <origin xyz="0 0 0.25"/>
      <geometry>
        <cylinder length="0.5" radius="0.2"/>
      </geometry>
      <material name="yellow"/>
    </visual>
  </link>

  <joint name="base_link_to_link1" type="continuous">
    <axis xyz="0 0 1"/>
    <origin xyz="0 0 1"/>
    <parent link="base_link"/>
    <child link="link1"/>
  </joint>


<!--  link1-->
  <link name="link1">
    <visual>
      <origin xyz="1 0 -0.25"/>
      <geometry>
        <box size="2.0 0.4 0.5" />
      </geometry>
      <origin rpy="0 0 0" xyz="0 0 0"/>
      <material name="blue"/>
    </visual>
  </link>

  <link name="link1_visual">
    <visual>
      <origin xyz="0 0 0"/>
      <geometry>
       <cylinder length="0.5" radius="0.2"/>
      </geometry>
      <material name="blue"/>
    </visual>
  </link>

  <joint name="link1_to_link1_visual" type="fixed">
    <origin xyz="0 0 -0.25"/>
    <parent link="link1"/>
    <child link="link1_visual"/>
  </joint>

<!--  link2-->
  <link name="link2">
    <visual>
      <origin xyz="1 0 -0.25"/>
      <geometry>
        <box size="2.0 0.4 0.5" />
      </geometry>
      <material name="red"/>
    </visual>
  </link>

  <joint name="link1_to_link2" type="continuous">
    <axis xyz="0 0 1"/>
    <origin xyz="2 0 0"/>
    <parent link="link1"/>
    <child link="link2"/>
  </joint>

  <link name="link2_visual">
    <visual>
      <origin xyz="0 0 0"/>
      <geometry>
       <cylinder length="0.5" radius="0.2"/>
      </geometry>
      <material name="red"/>
    </visual>
  </link>

  <joint name="link2_to_link2_visual" type="fixed">
    <origin xyz="0 0 -0.25"/>
    <parent link="link2"/>
    <child link="link2_visual"/>
  </joint>

<!--  <link name="EE_link">-->
  <link name="EE_link">
    <visual>
      <origin xyz="0 0 -0.50"/>
      <geometry>
        <cylinder length="0.8" radius="0.05"/>
      </geometry>
      <material name="green"/>
    </visual>
  </link>

  <joint name="link2_to_EE_link" type="prismatic">
    <axis xyz="0 0 1"/>
    <origin xyz="2 0 0"/>
    <parent link="link2"/>
    <child link="EE_link"/>
    <limit effort="1000.0" lower="-1" upper ="1" velocity ="0.5" />
  </joint>


</robot>